Workbook
Name capa1: Producten!$H$8:$H$15
Name capa2: Producten!$H$42:$H$45
Name capa3: Producten!$H$16:$H$33
Name capa4: Producten!$H$21:$H$33
Name capa5: Producten!$H$34:$H$41
Name capa6: Producten!$H$46:$H$52
Name capa7: Producten!$H$53:$H$56
Name fase1: Productselectie!$B$4:$B$5
Name fase11: Productselectie!$B$4:$E$5
Name merk1: Productselectie!$B$12:$B$13
Name merk11: Productselectie!$B$12:$E$13
Name merk2: Productselectie!$F$12:$F$14
Name merk21: Productselectie!$F$12:$I$14
Name omvo1: Productselectie!$B$21
Name omvo11: Productselectie!$B$21:$E$21
Name omvo2: Productselectie!$F$21
Name omvo21: Productselectie!$F$21:$I$21
Name omvo3: Productselectie!$B$25:$B$26
Name omvo31: Productselectie!$B$25:$E$26
Name omvo4: Productselectie!$F$25
Name omvo41: Productselectie!$F$25:$I$25
Name omvo5: Productselectie!$J$25:$J$26
Name omvo51: Productselectie!$J$25:$M$26
Name ParticulierJaJa: BTW!$S$55:$X$62
Name ParticulierJaNee: BTW!$S$45:$X$52
Name ParticulierNeeJa: BTW!$S$75:$Y$82
Name ParticulierNeeNee: BTW!$S$65:$X$72
Name ZakelijkJaJa: BTW!$S$85:$X$92
Name ZakelijkJaNee: BTW!$S$95:$X$102
Name ZakelijkNeeJa: BTW!$S$115:$X$122
Name ZakelijkNeeNee: BTW!$S$105:$X$112

Sheet Calculator
C2: Rendementscalculator
C3: Versie 67
C5: Klantgegevens
C6: Vul de gegevens van de klant in.
C8: Voor- en achternaam | H8: Jan Modaal
C10: Straat en huisnummer | H10: Hoogstraat 20
AC11: Contract
C12: Postcode en plaats | H12: 3552XM | K12: Utrecht | AC12: Vast
AC13: Variabel
C14: E-mailadres | H14: jan@modaal.nl | AC14: Dynamisch
C16: Telefoonnummer | H16: 0612345678
C18: Stroom
C19: Vul de gegevens van het energiecontract in van de klant.
C21: Overeenkomst
C23: Leverancier | G23: De huidige leverancier van de klant. | R23: Vattenfall
C25: Huidig contract | G25: Het soort contract dat de klant nu heeft. | R25: Variabel
C28: Levering
AC29: Zonnepanelen
C30: Verbruik | G30: De stroom die de klant van het net verbruikt (jaarnota). | R30: 3500 | U30: kWh
C32: Teruglevering | G32: De stroom die de klant teruglevert aan het net (jaarnota). | R32: 2500 | U32: kWh | V32: =IF(ISERROR(1-R36/R34),0,1-R36/R34) -> 0.71428571 | AC32: Aantal zonnepanelen | AD32: 10
C34: Opwek | G34: De stroom die de klant per jaar opwekt (app van zonnepanelen). | R34: 3500 | U34: kWh | AC34: Opwekvermogen per zonnepaneel | AD34: 410 | AE34: Wp
C36: Direct verbruik | G36: De opgewekte stroom die de klant direct verbruikt. | R36: =R34-R32 -> 1000 | U36: kWh | V36: =IF(ISERROR(R36/R34),0,R36/R34) -> 0.28571429 | AC36: Rendementspercentage | AD36: 0.85
C38: Totaal verbruik | G38: De totale hoeveelheid stroom die de klant gebruikt. | R38: =R30+R36 -> 4500 | U38: kWh | AC38: Opwek per jaar | AD38: =AD32*AD34*AD36 -> 3485
C40: Saldo | G40: De stroom die de klant netto inkoopt (+) of teruglevert (-). | R40: =R38-R34 -> 1000 | U40: kWh
C43: Financieel
C45: Vaste leveringskosten | G45: De vaste leveringskosten die de klant betaalt voor stroom | S45: 8.99 | U45: per maand inclusief BTW
C47: Leveringstarief | G47: Het tarief exclusief energiebelasting dat de klant nu betaalt | S47: 0.18 | U47: per kWh inclusief BTW
S48: 0.1
C49: Terugleverkosten | G49: De terugleverkosten die de huidige leverancier rekent. | S49: 0.15 | U49: per kWh inclusief BTW
C51: Terugleververgoeding | G51: De vergoeding die klant ontvangt. | S51: 0.14 | U51: per kWh
C54: Financieel nadeel afschaffen saldering
C56: Oorspronkelijke kosten | G56: Dit betaalde de klant zonder terugleveringskosten | R56: ='financieel nadeel'!G31 -> 411 | U56: per jaar
C58: Huidige kosten | G58: Dit betaalt de klant nu voor stroom. | R58: ='financieel nadeel'!M31 -> 786 | U58: per jaar
C60: Na afschaffen saldering | G60: Dit gaat de klant betalen zonder saldering | R60: ='financieel nadeel'!S31 -> 1168 | U60: per jaar
C62: Financieel nadeel | G62: Hogere kosten door einde saldering (t.o.v. oorspronkelijke kosten). | R62: =R60-R56 -> 757 | U62: per jaar
R63: =R62/12 -> 63.083333 | U63: per maand
C66: Toekomstig stroomverbruik
C67: Nederland is in 2050 volledig van het gas af. Nederlandse huishoudens gaan in de komende jaren 2 tot 4x zoveel stroom verbruiken. Wat zijn de verwachtingen met betrekking tot extra stroomverbruik in de komende jaren?
C69: Van het gas af
C71: Verbruik | G71: Huidig gasverbruik invullen vanaf de jaarnota. | R71: 1200 | U71: m3
...

Sheet financieel nadeel
A2: Contract | C2: Verbruik | F2: Leveringstarief | K2: Energiebelasting | O2: Leveringstarief
A3: =Calculator!R25 -> Variabel | C3: =Calculator!R30 -> 3500 | D3: kWh | F3: exclusief energiebelasting | O3: inclusief energiebelasting
G4: =Calculator!S47 -> 0.18 | H4: per kWh | K4: =Jaargegevens!M9 -> 0.12286 | L4: per kWh | O4: =G4+K4 -> 0.30286 | P4: per kWh
C6: Teruglevering | F6: Terugleververgoeding | K6: Terugleververgoeding | O6: Terugleverkosten | S6: Vaste leveringskosten
C7: =Calculator!R32 -> 2500 | D7: kWh | F7: (boven saldering) | K7: (bij saldering met verbruik) | O7: =IF(A3="Dynamisch",0,Calculator!S49) -> 0.15 | P7: per kWh | S7: =Calculator!S45 -> 8.99 | T7: per maand
G8: =IF(A3="Dynamisch",0,Calculator!S51) -> 0.14 | H8: per kWh | K8: =O4 -> 0.30286 | L8: per kWh
C10: Na afschaffing saldering wordt uitgegaan van een teruglevergoeding gelijk aan terugleverkosten In de berekening beiden € 0,00)
G13: Oorspronkelijk kosten | M13: Huidige kosten | S13: na afschaffing saldering
A15: Verbruik | C15: =C3 -> 3500 | D15: x | E15: =G4 -> 0.18 | F15: = | G15: =ROUND(C15*E15,0) -> 630 | I15: =C15 -> 3500 | J15: x | K15: =E15 -> 0.18 | L15: = | M15: =ROUND(I15*K15,0) -> 630 | O15: =I15 -> 3500 | P15: x | Q15: =K15 -> 0.18 | R15: = | S15: =ROUND(O15*Q15,0) -> 630
A17: Teruglevering (saldering) | C17: =MIN(C7,C15) -> 2500 | D17: x | E17: =G4 -> 0.18 | F17: = | G17: =-ROUND(C17*E17,0) -> -450 | I17: =C17 -> 2500 | J17: x | K17: =E17 -> 0.18 | L17: = | M17: =-ROUND(I17*K17,0) -> -450 | P17: x | Q17: =K17 -> 0.18 | R17: = | S17: =-ROUND(O17*Q17,0) -> 0
C18: - | G18: - | I18: - | M18: - | S18: -
A19: Per saldo | C19: =C15-C17 -> 1000 | G19: =SUM(G14:G18) -> 180 | I19: =I15-I17 -> 1000 | M19: =SUM(M14:M18) -> 180 | S19: =SUM(S14:S18) -> 630
A21: Energiebelasting | C21: =C19 -> 1000 | D21: x | E21: =K4 -> 0.12286 | F21: = | G21: =ROUND(C21*E21,0) -> 123 | I21: =I19 -> 1000 | J21: x | K21: =E21 -> 0.12286 | L21: = | M21: =ROUND(I21*K21,0) -> 123 | O21: =O15 -> 3500 | P21: x | Q21: =K21 -> 0.12286 | R21: = | S21: =ROUND(O21*Q21,0) -> 430
A23: Teruglevering (boven saldering) | C23: =C7-C17 -> 0 | D23: x | E23: =G8 -> 0.14 | F23: = | G23: =-ROUND(C23*E23,0) -> 0 | I23: =C23 -> 0 | J23: x | K23: =E23 -> 0.14 | L23: = | M23: =-ROUND(I23*K23,0) -> 0 | O23: =C7 -> 2500 | P23: x | Q23: 0 | R23: = | S23: =-ROUND(O23*Q23,0) -> 0
A25: Terugleverkosten | C25: =C7 -> 2500 | D25: x | E25: 0 | F25: = | G25: =ROUND(C25*E25,0) -> 0 | I25: =C25 -> 2500 | J25: x | K25: =O7 -> 0.15 | L25: = | M25: =ROUND(I25*K25,0) -> 375 | O25: =I25 -> 2500 | P25: x | Q25: =Q23 -> 0 | R25: = | S25: =ROUND(O25*Q25,0) -> 0
G26: - | M26: - | S26: -
G27: =SUM(G18:G26) -> 303 | M27: =SUM(M18:M26) -> 678 | S27: =SUM(S18:S26) -> 1060
A29: Vaste leveringskosten | C29: 12 | D29: x | E29: =S7 -> 8.99 | F29: = | G29: =ROUND(C29*E29,0) -> 108 | I29: =C29 -> 12 | J29: x | K29: =E29 -> 8.99 | L29: = | M29: =ROUND(I29*K29,0) -> 108 | O29: =I29 -> 12 | P29: x | Q29: =K29 -> 8.99 | R29: = | S29: =ROUND(O29*Q29,0) -> 108
G30: - | M30: - | S30: -
G31: =SUM(G26:G30) -> 411 | M31: =SUM(M26:M30) -> 786 | S31: =SUM(S26:S30) -> 1168
G32: = | M32: = | S32: =

Sheet Productselectie
B1: Keuze-menu fase | F1: tekst na wijziging eerdere selectie | G1: maak andere keuze
B3: Fase | C3: Kosten
B4: 1 fase | C4: 0 | D4: merk1
B5: 3 fase | C5: 0 | D5: merk2
C6: =VLOOKUP(Calculator!R84,fase11,3) -> merk2 | D6: =CONCATENATE(C6,"1") -> merk21
C7: =IF(ISERROR(VLOOKUP(Calculator!Q86,INDIRECT(Productselectie!C6),1,FALSE)),G1,VLOOKUP(Calculator!Q86,INDIRECT(Productselectie!C6),1,FALSE)) -> AlphaESS Smile 3 fase
B9: Keuzemenu's merk
B11: =B4 -> 1 fase | C11: Kosten | F11: =B5 -> 3 fase | G11: Kosten
B12: AlphaESS Smile 1 fase | C12: 0 | D12: omvo1 | F12: AlphaESS Smile 3 fase | G12: 0 | H12: omvo3
B13: HYXI HYX 1 fase | C13: 0 | D13: omvo2 | F13: AplhaESS Storion 3 fase | G13: 0 | H13: omvo4
F14: HYXI HYX 3 fase | G14: 0 | H14: omvo5
C15: =VLOOKUP(Calculator!Q86,INDIRECT(D6),3) -> omvo3 | D15: =CONCATENATE(C15,"1") -> omvo31
C16: =IF(ISERROR(VLOOKUP(Calculator!Q88,INDIRECT(Productselectie!C15),1,FALSE)),G1,VLOOKUP(Calculator!Q88,INDIRECT(Productselectie!C15),1,FALSE)) -> 10,0 kW (Hybride)
C17: =VLOOKUP(Calculator!Q88,INDIRECT(Productselectie!D15),2) -> 0
B18: Keuzemenu's omvormer
B20: =B12 -> AlphaESS Smile 1 fase | C20: Kosten | F20: =B13 -> HYXI HYX 1 fase | G20: Kosten
B21: 5,0 kW (Hybride) | C21: 0 | D21: capa1 | F21: 5,0 kW (Hybride) | G21: 0 | H21: capa2
B24: =F12 -> AlphaESS Smile 3 fase | C24: Kosten | F24: =F13 -> AplhaESS Storion 3 fase | G24: Kosten | J24: =F14 -> HYXI HYX 3 fase | K24: Kosten
B25: 10,0 kW (Hybride) | C25: 0 | D25: capa3 | F25: 30,0 - 50,0 kW (Hybride) | G25: 0 | H25: capa5 | J25: 10,0 kW (Hybride) | K25: 0 | L25: capa6
B26: 20,0 kW (Hybride) | C26: 2000 | D26: capa4 | J26: 6,0 - 13,0 kW (All-in-One) | K26: 0 | L26: capa7
C27: =VLOOKUP(Calculator!Q88,INDIRECT(D15),3) -> capa3
C28: =IF(ISERROR(VLOOKUP(Calculator!M90,INDIRECT(Productselectie!C27),1,FALSE)),G1,VLOOKUP(Calculator!M90,INDIRECT(Productselectie!C27),1,FALSE)) -> AlphaESS Smile3,6 binnen 21,85 (3 Fase)

Sheet Producten
H4: =I4&" "&M4&" ("&N4&")" -> AlphaESS 20 kW Omvormer (3 Fase) | I4: AlphaESS | M4: 20 kW Omvormer | N4: 3 Fase | T4: 20 | U4: 2000 | V4: 2000 | W4: 2000 | X4: 2000 | Y4: 2000
D6: capa | W6: factuur | X6: factuur | Y6: factuur | Z6: factuur
A7: 1 | B7: 2 | C7: 3 | D7: 4 | E7: 5 | F7: 6 | G7: 7 | H7: Product | I7: Merk | J7: Model | K7: Module | L7: Aantal | M7: Capaciteit | N7: Aansluiting | O7: RTE | P7: Cycles | Q7: Cycles Tonen | R7: Restcapaciteit | S7: Garantie | T7: Omvormer | U7: Prijs in BTW | V7: Prijs Ex BTW | W7: Batterijen | X7: Installatie | Y7: BTW teruggave | Z7: buiten BTW | AA7: Noodstroom | AB7: Prijs per kWh | AC7: IP Omvormer | AD7: IP Batterij | AE7: Geschikt Buiten | AF7: Breedte (mm) | AG7: Diepte (mm) | AH7: Hoogte (mm) | AI7: Totale Hoogte (mm) | AJ7: Gewicht Module (kg) | AK7: Max modules in toren | AL7: Aansturing | AM7: Bevestiging | AN7: Opmerkingen | AO7: BTW per saldo
A8: 1 | H8: =I8&" "&" "&J8&" "&M8&" ("&N8&")" -> AlphaESS Smile3,6 binnen 3,64 (1 Fase) | I8: AlphaESS | J8: Smile3,6 binnen | K8: =(46/12)*0.95 -> 3.6416667 | L8: 1 | M8: =ROUND(K8*L8,2) -> 3.64 | N8: 1 Fase | O8: 0.96 | P8: 10000 | Q8: =P8 -> 10000 | R8: 0.7 | S8: 10 | T8: 5 | U8: 7499 | V8: =U8/1.21 -> 6197.5207 | W8: =U8-X8 -> 6499 | X8: 1000 | Y8: =U8-Z8 -> 7499 | AA8: Basis | AB8: =U8/M8 -> 2060.1648 | AC8: IP65 | AD8: IP21 | AE8: Nee | AF8: 610 | AG8: 213 | AH8: 435 | AI8: 851 | AJ8: 39.2 | AK8: 4 | AN8: Basis configuratie, alleen binnen IP21
A9: 1 | H9: =I9&" "&" "&J9&" "&M9&" ("&N9&")" -> AlphaESS Smile3,6 binnen 7,28 (1 Fase) | I9: AlphaESS | J9: Smile3,6 binnen | K9: =(46/12)*0.95 -> 3.6416667 | L9: 2 | M9: =ROUND(K9*L9,2) -> 7.28 | N9: 1 Fase | O9: 0.96 | P9: 10000 | Q9: =P9 -> 10000 | R9: 0.7 | S9: 10 | T9: 5 | U9: 8999 | V9: =U9/1.21 -> 7437.1901 | W9: =U9-X9 -> 7999 | X9: 1000 | Y9: =U9-Z9 -> 8999 | AA9: Basis | AB9: =U9/M9 -> 1236.1264 | AC9: IP65 | AD9: IP21 | AE9: Nee | AF9: 610 | AG9: 213 | AH9: 435 | AI9: 1286 | AJ9: 39.2 | AK9: 4
A10: 1 | H10: =I10&" "&" "&J10&" "&M10&" ("&N10&")" -> AlphaESS Smile3,6 binnen 10,93 (1 Fase) | I10: AlphaESS | J10: Smile3,6 binnen | K10: =(46/12)*0.95 -> 3.6416667 | L10: 3 | M10: =ROUND(K10*L10,2) -> 10.93 | N10: 1 Fase | O10: 0.96 | P10: 10000 | Q10: =P10 -> 10000 | R10: 0.7 | S10: 10 | T10: 5 | U10: 10499 | V10: =U10/1.21 -> 8676.8595 | W10: =U10-X10 -> 9499 | X10: 1000 | Y10: =U10-Z10 -> 10499 | AA10: Basis | AB10: =U10/M10 -> 960.56725 | AC10: IP65 | AD10: IP21 | AE10: Nee | AF10: 610 | AG10: 213 | AH10: 435 | AI10: 1721 | AJ10: 39.2 | AK10: 4
A11: 1 | H11: =I11&" "&" "&J11&" "&M11&" ("&N11&")" -> AlphaESS Smile3,6 binnen 14,57 (1 Fase) | I11: AlphaESS | J11: Smile3,6 binnen | K11: =(46/12)*0.95 -> 3.6416667 | L11: 4 | M11: =ROUND(K11*L11,2) -> 14.57 | N11: 1 Fase | O11: 0.96 | P11: 10000 | Q11: 10000 | R11: 0.7 | S11: 10 | T11: 5 | U11: 11999 | V11: =U11/1.21 -> 9916.5289 | W11: =U11-X11 -> 10999 | X11: 1000 | Y11: =U11-Z11 -> 11999 | AA11: Basis | AB11: =U11/M11 -> 823.54152 | AC11: IP65 | AD11: IP21 | AE11: Nee | AF11: 610 | AG11: 213 | AH11: 435 | AI11: 2156 | AJ11: 39.2 | AK11: 4 | AN11: Maximum voor 1-fase systeem
A12: 1 | H12: =I12&" "&" "&J12&" "&M12&" ("&N12&")" -> AlphaESS Smile9,3 buiten 9,3 (1 Fase) | I12: AlphaESS | J12: Smile9,3 buiten | K12: 9.3 | L12: 1 | M12: =ROUND(K12*L12,2) -> 9.3 | N12: 1 Fase | O12: 0.98 | P12: 10000 | Q12: 10000 | R12: 0.7 | S12: 10 | T12: 10 | U12: =5999+L12*3000 -> 8999 | V12: =U12/1.21 -> 7437.1901 | W12: =U12-X12 -> 7999 | X12: 1000 | Y12: =U12-Z12 -> 8999 | AA12: Basis | AB12: =U12/M12 -> 967.63441 | AC12: IP65 | AD12: IP65 | AE12: Ja | AF12: 610 | AG12: 210 | AH12: 634 | AI12: 850 | AJ12: 81 | AK12: 3 | AN12: IP65 batterij = buitengeschikt, vanaf hier 1 fase
A13: 1 | H13: =I13&" "&" "&J13&" "&M13&" ("&N13&")" -> AlphaESS Smile9,3 buiten 18,6 (1 Fase) | I13: AlphaESS | J13: Smile9,3 buiten | K13: 9.3 | L13: 2 | M13: =ROUND(K13*L13,2) -> 18.6 | N13: 1 Fase | O13: 0.98 | P13: 10000 | Q13: 10000 | R13: 0.7 | S13: 10 | T13: 10 | U13: =5999+L13*3000 -> 11999 | V13: =U13/1.21 -> 9916.5289 | W13: =U13-X13 -> 10999 | X13: 1000 | Y13: =U13-Z13 -> 11999 | AA13: Basis | AB13: =U13/M13 -> 645.10753 | AC13: IP65 | AD13: IP65 | AE13: Ja | AF13: 610 | AG13: 210 | AH13: 634 | AI13: 1068 | AJ13: 81 | AK13: 3
A14: 1 | H14: =I14&" "&" "&J14&" "&M14&" ("&N14&")" -> AlphaESS Smile9,3 buiten 27,9 (1 Fase) | I14: AlphaESS | J14: Smile9,3 buiten | K14: 9.3 | L14: 3 | M14: =ROUND(K14*L14,2) -> 27.9 | N14: 1 Fase | O14: 0.98 | P14: 10000 | Q14: 10000 | R14: 0.7 | S14: 10 | T14: 10 | U14: =5999+L14*3000 -> 14999 | V14: =U14/1.21 -> 12395.868 | W14: =U14-X14 -> 13999 | X14: 1000 | Y14: =U14-Z14 -> 13999 | Z14: 1000 | AA14: Basis | AB14: =U14/M14 -> 537.59857 | AC14: IP65 | AD14: IP65 | AE14: Ja | AF14: 610 | AG14: 210 | AH14: 634 | AI14: 1286 | AJ14: 81 | AK14: 3 | AN14: BTW grens €13.999 overschreden, factuur gesplitst
A15: 1 | H15: =I15&" "&" "&J15&" "&M15&" ("&N15&")" -> AlphaESS Smile9,3 buiten 37,2 (1 Fase) | I15: AlphaESS | J15: Smile9,3 buiten | K15: 9.3 | L15: 4 | M15: =ROUND(K15*L15,2) -> 37.2 | N15: 1 Fase | O15: 0.98 | P15: 10000 | Q15: 10000 | R15: 0.7 | S15: 10 | T15: 10 | U15: =5999+L15*3000 -> 17999 | V15: =U15/1.21 -> 14875.207 | W15: =U15-X15 -> 16999 | X15: 1000 | Y15: =U15-Z15 -> 17999 | AA15: Basis | AB15: =U15/M15 -> 483.84409 | AC15: IP65 | AD15: IP65 | AE15: Ja | AF15: 1420 | AG15: 210 | AH15: 634 | AI15: 1684 | AJ15: 81 | AK15: 3 | AN15: Grootste 9.3 opstelling 1-fase | AO15: =Y15-Y15/1.21-5*15*M15-4*50 -> 133.79339
C16: 3 | H16: =I16&" "&" "&J16&" "&M16&" ("&N16&")" -> AlphaESS Smile3,6 binnen 3,64 (3 Fase) | I16: AlphaESS | J16: Smile3,6 binnen | K16: =(46/12)*0.95 -> 3.6416667 | L16: 1 | M16: =ROUND(K16*L16,2) -> 3.64 | N16: 3 Fase | O16: 0.96 | P16: 10000 | Q16: =P16 -> 10000 | R16: 0.7 | S16: 10 | T16: 10 | U16: 7499 | V16: =U16/1.21 -> 6197.5207 | W16: =U16-X16 -> 6499 | X16: 1000 | Y16: =U16-Z16 -> 7499 | AA16: Basis | AB16: =U16/M16 -> 2060.1648 | AC16: IP65 | AD16: IP21 | AE16: Nee | AF16: 610 | AG16: 213 | AH16: 435 | AI16: 851 | AJ16: 39.2 | AK16: 4 | AN16: 3 fase 3,6 kWh modules, flexibel in opbouw
C17: 3 | H17: =I17&" "&" "&J17&" "&M17&" ("&N17&")" -> AlphaESS Smile3,6 binnen 7,28 (3 Fase) | I17: AlphaESS | J17: Smile3,6 binnen | K17: =(46/12)*0.95 -> 3.6416667 | L17: 2 | M17: =ROUND(K17*L17,2) -> 7.28 | N17: 3 Fase | O17: 0.96 | P17: 10000 | Q17: =P17 -> 10000 | R17: 0.7 | S17: 10 | T17: 10 | U17: 8999 | V17: =U17/1.21 -> 7437.1901 | W17: =U17-X17 -> 7999 | X17: 1000 | Y17: =U17-Z17 -> 8999 | AA17: Basis | AB17: =U17/M17 -> 1236.1264 | AC17: IP65 | AD17: IP21 | AE17: Nee | AF17: 610 | AG17: 213 | AH17: 435 | AI17: 1286 | AJ17: 39.2 | AK17: 4
C18: 3 | H18: =I18&" "&" "&J18&" "&M18&" ("&N18&")" -> AlphaESS Smile3,6 binnen 10,93 (3 Fase) | I18: AlphaESS | J18: Smile3,6 binnen | K18: =(46/12)*0.95 -> 3.6416667 | L18: 3 | M18: =ROUND(K18*L18,2) -> 10.93 | N18: 3 Fase | O18: 0.96 | P18: 10000 | Q18: =P18 -> 10000 | R18: 0.7 | S18: 10 | T18: 10 | U18: 10499 | V18: =U18/1.21 -> 8676.8595 | W18: =U18-X18 -> 9499 | X18: 1000 | Y18: =U18-Z18 -> 10499 | AA18: Basis | AB18: =U18/M18 -> 960.56725 | AC18: IP65 | AD18: IP21 | AE18: Nee | AF18: 610 | AG18: 213 | AH18: 435 | AI18: 1721 | AJ18: 39.2 | AK18: 4
C19: 3 | H19: =I19&" "&" "&J19&" "&M19&" ("&N19&")" -> AlphaESS Smile3,6 binnen 14,57 (3 Fase) | I19: AlphaESS | J19: Smile3,6 binnen | K19: =(46/12)*0.95 -> 3.6416667 | L19: 4 | M19: =ROUND(K19*L19,2) -> 14.57 | N19: 3 Fase | O19: 0.96 | P19: 10000 | Q19: =P19 -> 10000 | R19: 0.7 | S19: 10 | T19: 10 | U19: 11999 | V19: =U19/1.21 -> 9916.5289 | W19: =U19-X19 -> 10999 | X19: 1000 | Y19: =U19-Z19 -> 11999 | AA19: Basis | AB19: =U19/M19 -> 823.54152 | AC19: IP65 | AD19: IP21 | AE19: Nee | AF19: 610 | AG19: 213 | AH19: 435 | AI19: 2156 | AJ19: 39.2 | AK19: 4
C20: 3 | H20: =I20&" "&" "&J20&" "&M20&" ("&N20&")" -> AlphaESS Smile3,6 binnen 18,21 (3 Fase) | I20: AlphaESS | J20: Smile3,6 binnen | K20: =(46/12)*0.95 -> 3.6416667 | L20: 5 | M20: =ROUND(K20*L20,2) -> 18.21 | N20: 3 Fase | O20: 0.96 | P20: 10000 | Q20: =P20 -> 10000 | R20: 0.7 | S20: 10 | T20: 10 | U20: 13499 | V20: =U20/1.21 -> 11156.198 | W20: =U20-X20 -> 12499 | X20: 1000 | Y20: =U20-Z20 -> 13499 | AA20: Basis | AB20: =U20/M20 -> 741.29599 | AC20: IP65 | AD20: IP21 | AE20: Nee | AF20: 1420 | AG20: 213 | AH20: 435 | AI20: 1305 | AJ20: 39.2 | AK20: 4 | AN20: Dubbele rack vanaf hier
C21: 3 | D21: 4 | H21: =I21&" "&" "&J21&" "&M21&" ("&N21&")" -> AlphaESS Smile3,6 binnen 21,85 (3 Fase) | I21: AlphaESS | J21: Smile3,6 binnen | K21: =(46/12)*0.95 -> 3.6416667 | L21: 6 | M21: =ROUND(K21*L21,2) -> 21.85 | N21: 3 Fase | O21: 0.96 | P21: 10000 | Q21: =P21 -> 10000 | R21: 0.7 | S21: 10 | T21: 10 | U21: 14999 | V21: =U21/1.21 -> 12395.868 | W21: =U21-X21 -> 13999 | X21: 1000 | Y21: =U21-Z21 -> 13999 | Z21: 1000 | AA21: Basis | AB21: =U21/M21 -> 686.45309 | AC21: IP65 | AD21: IP21 | AE21: Nee | AF21: 1420 | AG21: 213 | AH21: 435 | AI21: 1721 | AJ21: 39.2 | AK21: 4 | AN21: BTW grens €13.999 overschreden, factuur gesplitst
C22: 3 | D22: 4 | H22: =I22&" "&" "&J22&" "&M22&" ("&N22&")" -> AlphaESS Smile3,6 binnen 29,13 (3 Fase) | I22: AlphaESS | J22: Smile3,6 binnen | K22: =(46/12)*0.95 -> 3.6416667 | L22: 8 | M22: =ROUND(K22*L22,2) -> 29.13 | N22: 3 Fase | O22: 0.96 | P22: 10000 | Q22: =P22 -> 10000 | R22: 0.7 | S22: 10 | T22: 10 | U22: 17999 | V22: =U22/1.21 -> 14875.207 | W22: =U22-X22 -> 16999 | X22: 1000 | Y22: =U22-Z22 -> 17999 | AA22: Basis | AB22: =U22/M22 -> 617.88534 | AC22: IP65 | AD22: IP21 | AE22: Nee | AF22: 1420 | AG22: 213 | AH22: 435 | AI22: 2156 | AJ22: 39.2 | AK22: 4 | AN22: 8 modules dubbele rack | AO22: =Y22-Y22/1.21-5*15*M22-4*50 -> 739.04339
C23: 3 | D23: 4 | H23: =I23&" "&" "&J23&" "&M23&" ("&N23&")" -> AlphaESS Smile3,6 binnen 36,42 (3 Fase) | I23: AlphaESS | J23: Smile3,6 binnen | K23: =(46/12)*0.95 -> 3.6416667 | L23: 10 | M23: =ROUND(K23*L23,2) -> 36.42 | N23: 3 Fase | O23: 0.96 | P23: 10000 | Q23: =P23 -> 10000 | R23: 0.7 | S23: 10 | T23: 10 | U23: 20999 | V23: =U23/1.21 -> 17354.545 | W23: =U23-X23 -> 19999 | X23: 1000 | Y23: =U23-Z23 -> 20999 | AA23: Basis | AB23: =U23/M23 -> 576.5788 | AC23: IP65 | AD23: IP21 | AE23: Nee | AF23: 2230 | AG23: 213 | AH23: 435 | AI23: 1740 | AJ23: 39.2 | AK23: 4 | AN23: Triple rack | AO23: =Y23-Y23/1.21-5*15*M23-4*50 -> 712.95455
C24: 3 | D24: 4 | H24: =I24&" "&" "&J24&" "&M24&" ("&N24&")" -> AlphaESS Smile3,6 binnen 43,7 (3 Fase) | I24: AlphaESS | J24: Smile3,6 binnen | K24: =(46/12)*0.95 -> 3.6416667 | L24: 12 | M24: =ROUND(K24*L24,2) -> 43.7 | N24: 3 Fase | O24: 0.96 | P24: 10000 | Q24: =P24 -> 10000 | R24: 0.7 | S24: 10 | T24: 10 | U24: 23999 | V24: =U24/1.21 -> 19833.884 | W24: =U24-X24 -> 22999 | X24: 1000 | Y24: =U24-Z24 -> 23999 | AA24: Basis | AB24: =U24/M24 -> 549.1762 | AC24: IP65 | AD24: IP21 | AE24: Nee | AF24: 2230 | AG24: 213 | AH24: 435 | AI24: 2156 | AJ24: 39.2 | AK24: 4 | AN24: Grootste 3.6kWh opstelling | AO24: =Y24-Y24/1.21-5*15*M24-4*50 -> 687.6157
C25: 3 | D25: 4 | H25: =I25&" "&" "&J25&" "&M25&" ("&N25&")" -> AlphaESS Smile9,3 buiten 9,3 (3 Fase) | I25: AlphaESS | J25: Smile9,3 buiten | K25: 9.3 | L25: 1 | M25: =ROUND(K25*L25,2) -> 9.3 | N25: 3 Fase | O25: 0.98 | P25: 10000 | Q25: 10000 | R25: 0.7 | S25: 10 | T25: 10 | U25: =5999+L25*3000 -> 8999 | V25: =U25/1.21 -> 7437.1901 | W25: =U25-X25 -> 7999 | X25: 1000 | Y25: =U25-Z25 -> 8999 | AA25: Basis | AB25: =U25/M25 -> 967.63441 | AC25: IP65 | AD25: IP65 | AE25: Ja | AF25: 610 | AG25: 210 | AH25: 634 | AI25: 850 | AJ25: 81 | AK25: 3 | AN25: Goede specs voor de prijs
C26: 3 | D26: 4 | H26: =I26&" "&" "&J26&" "&M26&" ("&N26&")" -> AlphaESS Smile9,3 buiten 18,6 (3 Fase) | I26: AlphaESS | J26: Smile9,3 buiten | K26: 9.3 | L26: 2 | M26: =ROUND(K26*L26,2) -> 18.6 | N26: 3 Fase | O26: 0.98 | P26: 10000 | Q26: 10000 | R26: 0.7 | S26: 10 | T26: 10 | U26: =5999+L26*3000 -> 11999 | V26: =U26/1.21 -> 9916.5289 | W26: =U26-X26 -> 10999 | X26: 1000 | Y26: =U26-Z26 -> 11999 | AA26: Basis | AB26: =U26/M26 -> 645.10753 | AC26: IP65 | AD26: IP65 | AE26: Ja | AF26: 610 | AG26: 210 | AH26: 634 | AI26: 1068 | AJ26: 81 | AK26: 3
C27: 3 | D27: 4 | H27: =I27&" "&" "&J27&" "&M27&" ("&N27&")" -> AlphaESS Smile9,3 buiten 27,9 (3 Fase) | I27: AlphaESS | J27: Smile9,3 buiten | K27: 9.3 | L27: 3 | M27: =ROUND(K27*L27,2) -> 27.9 | N27: 3 Fase | O27: 0.98 | P27: 10000 | Q27: 10000 | R27: 0.7 | S27: 10 | T27: 10 | U27: =5999+L27*3000 -> 14999 | V27: =U27/1.21 -> 12395.868 | W27: =U27-X27 -> 13999 | X27: 1000 | Y27: =U27-Z27 -> 13999 | Z27: 1000 | AA27: Basis | AB27: =U27/M27 -> 537.59857 | AC27: IP65 | AD27: IP65 | AE27: Ja | AF27: 610 | AG27: 210 | AH27: 634 | AI27: 1286 | AJ27: 81 | AK27: 3 | AN27: BTW grens €13.999 overschreden, factuur gesplitst
C28: 3 | D28: 4 | H28: =I28&" "&" "&J28&" "&M28&" ("&N28&")" -> AlphaESS Smile9,3 buiten 37,2 (3 Fase) | I28: AlphaESS | J28: Smile9,3 buiten | K28: 9.3 | L28: 4 | M28: =ROUND(K28*L28,2) -> 37.2 | N28: 3 Fase | O28: 0.98 | P28: 10000 | Q28: 10000 | R28: 0.7 | S28: 10 | T28: 10 | U28: =5999+L28*3000 -> 17999 | V28: =U28/1.21 -> 14875.207 | W28: =U28-X28 -> 16999 | X28: 1000 | Y28: =U28-Z28 -> 17999 | AA28: Basis | AB28: =U28/M28 -> 483.84409 | AC28: IP65 | AD28: IP65 | AE28: Ja | AF28: 1420 | AG28: 210 | AH28: 634 | AI28: 1684 | AJ28: 81 | AK28: 3 | AN28: Dubbele rack | AO28: =Y28-Y28/1.21-5*15*M28-4*50 -> 133.79339
C29: 3 | D29: 4 | H29: =I29&" "&" "&J29&" "&M29&" ("&N29&")" -> AlphaESS Smile9,3 buiten 46,5 (3 Fase) | I29: AlphaESS | J29: Smile9,3 buiten | K29: 9.3 | L29: 5 | M29: =ROUND(K29*L29,2) -> 46.5 | N29: 3 Fase | O29: 0.98 | P29: 10000 | Q29: 10000 | R29: 0.7 | S29: 10 | T29: 10 | U29: =5999+L29*3000 -> 20999 | V29: =U29/1.21 -> 17354.545 | W29: =U29-X29 -> 19999 | X29: 1000 | Y29: =U29-Z29 -> 20999 | AA29: Basis | AB29: =U29/M29 -> 451.5914 | AC29: IP65 | AD29: IP65 | AE29: Ja | AF29: 1420 | AG29: 210 | AH29: 634 | AI29: 1902 | AJ29: 81 | AK29: 3 | AN29: 5 modules dubbele rack | AO29: =Y29-Y29/1.21-5*15*M29-4*50 -> -43.045455
C30: 3 | D30: 4 | H30: =I30&" "&" "&J30&" "&M30&" ("&N30&")" -> AlphaESS Smile9,3 buiten 55,8 (3 Fase) | I30: AlphaESS | J30: Smile9,3 buiten | K30: 9.3 | L30: 6 | M30: =ROUND(K30*L30,2) -> 55.8 | N30: 3 Fase | O30: 0.98 | P30: 10000 | Q30: 10000 | R30: 0.7 | S30: 10 | T30: 10 | U30: =5999+L30*3000 -> 23999 | V30: =U30/1.21 -> 19833.884 | W30: =U30-X30 -> 22999 | X30: 1000 | Y30: =U30-Z30 -> 23999 | AA30: Basis | AB30: =U30/M30 -> 430.08961 | AC30: IP65 | AD30: IP65 | AE30: Ja | AF30: 1420 | AG30: 210 | AH30: 634 | AI30: 2120 | AJ30: 81 | AK30: 3 | AN30: 6 modules dubbele rack | AO30: =Y30-Y30/1.21-5*15*M30-4*50 -> -219.8843
C31: 3 | D31: 4 | H31: =I31&" "&" "&J31&" "&M31&" ("&N31&")" -> AlphaESS Smile9,3 buiten 74,4 (3 Fase) | I31: AlphaESS | J31: Smile9,3 buiten | K31: 9.3 | L31: 8 | M31: =ROUND(K31*L31,2) -> 74.4 | N31: 3 Fase | O31: 0.98 | P31: 10000 | Q31: 10000 | R31: 0.7 | S31: 10 | T31: 10 | U31: =5999+L31*3000 -> 29999 | V31: =U31/1.21 -> 24792.562 | W31: =U31-X31 -> 28999 | X31: 1000 | Y31: =U31-Z31 -> 29999 | AA31: Basis | AB31: =U31/M31 -> 403.21237 | AC31: IP65 | AD31: IP65 | AE31: Ja | AF31: 1830 | AG31: 210 | AH31: 634 | AI31: 1902 | AJ31: 81 | AK31: 3 | AN31: 8 modules triple rack | AO31: =Y31-Y31/1.21-5*15*M31-4*50 -> -573.56198
C32: 3 | D32: 4 | H32: =I32&" "&" "&J32&" "&M32&" ("&N32&")" -> AlphaESS Smile9,3 buiten 93 (3 Fase) | I32: AlphaESS | J32: Smile9,3 buiten | K32: 9.3 | L32: 10 | M32: =ROUND(K32*L32,2) -> 93 | N32: 3 Fase | O32: 0.98 | P32: 10000 | Q32: 10000 | R32: 0.7 | S32: 10 | T32: 10 | U32: =5999+L32*3000 -> 35999 | V32: =U32/1.21 -> 29751.24 | W32: =U32-X32 -> 34999 | X32: 1000 | Y32: =U32-Z32 -> 35999 | AA32: Basis | AB32: =U32/M32 -> 387.08602 | AC32: IP65 | AD32: IP65 | AE32: Ja | AF32: 2240 | AG32: 210 | AH32: 634 | AI32: 1902 | AJ32: 81 | AK32: 3 | AN32: 10 modules quad rack | AO32: =Y32-Y32/1.21-5*15*M32-4*50 -> -927.23967
C33: 3 | D33: 4 | H33: =I33&" "&" "&J33&" "&M33&" ("&N33&")" -> AlphaESS Smile9,3 buiten 111,6 (3 Fase) | I33: AlphaESS | J33: Smile9,3 buiten | K33: 9.3 | L33: 12 | M33: =ROUND(K33*L33,2) -> 111.6 | N33: 3 Fase | O33: 0.98 | P33: 10000 | Q33: 10000 | R33: 0.7 | S33: 10 | T33: 10 | U33: =5999+L33*3000 -> 41999 | V33: =U33/1.21 -> 34709.917 | W33: =U33-X33 -> 40999 | X33: 1000 | Y33: =U33-Z33 -> 41999 | AA33: Basis | AB33: =U33/M33 -> 376.33513 | AC33: IP65 | AD33: IP65 | AE33: Ja | AF33: 2240 | AG33: 210 | AH33: 634 | AI33: 2120 | AJ33: 81 | AK33: 3 | AN33: Grootste Smile configuratie | AO33: =Y33-Y33/1.21-5*15*M33-4*50 -> -1280.9174
E34: 5 | H34: =I34&" "&" "&J34&" "&M34&" ("&N34&")" -> AlphaESS Storion 72,3 (3 Fase) | I34: AlphaESS | J34: Storion | K34: 24.1 | L34: 3 | M34: =ROUND(K34*L34,2) -> 72.3 | N34: 3 Fase | O34: 0.98 | P34: 8000 | Q34: 8000 | R34: 0.7 | S34: 5 | T34: 30 | U34: 39999 | V34: =U34/1.21 -> 33057.025 | W34: =U34-X34 -> 38999 | X34: 1000 | Y34: =U34-Z34 -> 39999 | AA34: Volwaardig | AB34: =U34/M34 -> 553.23651 | AC34: IP55 | AD34: IP20 | AE34: Ja | AF34: 1120 | AG34: 1300 | AH34: 250 | AI34: 2050 | AJ34: 168 | AK34: 5 | AN34: Off-grid capable, 8000 cycli, 5 jaar garantie | AO34: =Y34-Y34/1.21-5*15*M34-4*50 -> 1319.4752
E35: 5 | H35: =I35&" "&" "&J35&" "&M35&" ("&N35&")" -> AlphaESS Storion 96,4 (3 Fase) | I35: AlphaESS | J35: Storion | K35: 24.1 | L35: 4 | M35: =ROUND(K35*L35,2) -> 96.4 | N35: 3 Fase | O35: 0.98 | P35: 8000 | Q35: 8000 | R35: 0.7 | S35: 5 | T35: 30 | U35: 43999 | V35: =U35/1.21 -> 36362.81 | W35: =U35-X35 -> 42999 | X35: 1000 | Y35: =U35-Z35 -> 43999 | AA35: Volwaardig | AB35: =U35/M35 -> 456.42116 | AC35: IP55 | AD35: IP20 | AE35: Ja | AF35: 1120 | AG35: 1300 | AH35: 250 | AI35: 2050 | AJ35: 168 | AK35: 5 | AO35: =Y35-Y35/1.21-5*15*M35-4*50 -> 206.19008
E36: 5 | H36: =I36&" "&" "&J36&" "&M36&" ("&N36&")" -> AlphaESS Storion 120,5 (3 Fase) | I36: AlphaESS | J36: Storion | K36: 24.1 | L36: 5 | M36: =ROUND(K36*L36,2) -> 120.5 | N36: 3 Fase | O36: 0.98 | P36: 8000 | Q36: 8000 | R36: 0.7 | S36: 5 | T36: 30 | U36: 47999 | V36: =U36/1.21 -> 39668.595 | W36: =U36-X36 -> 46999 | X36: 1000 | Y36: =U36-Z36 -> 47999 | AA36: Volwaardig | AB36: =U36/M36 -> 398.33195 | AC36: IP55 | AD36: IP20 | AE36: Ja | AF36: 1120 | AG36: 1300 | AH36: 250 | AI36: 2050 | AJ36: 168 | AK36: 5 | AO36: =Y36-Y36/1.21-5*15*M36-4*50 -> -907.09504
E37: 5 | H37: =I37&" "&" "&J37&" "&M37&" ("&N37&")" -> AlphaESS Storion 144,6 (3 Fase) | I37: AlphaESS | J37: Storion | K37: 24.1 | L37: 6 | M37: =ROUND(K37*L37,2) -> 144.6 | N37: 3 Fase | O37: 0.98 | P37: 8000 | Q37: 8000 | R37: 0.7 | S37: 5 | T37: 30 | U37: 61999 | V37: =U37/1.21 -> 51238.843 | W37: =U37-X37 -> 60999 | X37: 1000 | Y37: =U37-Z37 -> 61999 | AA37: Volwaardig | AB37: =U37/M37 -> 428.7621 | AC37: IP55 | AD37: IP20 | AE37: Ja | AF37: 2240 | AG37: 1300 | AH37: 250 | AI37: 2050 | AJ37: 168 | AK37: 5 | AN37: Dubbele kast vanaf 6 modules | AO37: =Y37-Y37/1.21-5*15*M37-4*50 -> -284.84298
E38: 5 | H38: =I38&" "&" "&J38&" "&M38&" ("&N38&")" -> AlphaESS Storion 168,7 (3 Fase) | I38: AlphaESS | J38: Storion | K38: 24.1 | L38: 7 | M38: =ROUND(K38*L38,2) -> 168.7 | N38: 3 Fase | O38: 0.98 | P38: 8000 | Q38: 8000 | R38: 0.7 | S38: 5 | T38: 30 | U38: 65999 | V38: =U38/1.21 -> 54544.628 | W38: =U38-X38 -> 64999 | X38: 1000 | Y38: =U38-Z38 -> 65999 | AA38: Volwaardig | AB38: =U38/M38 -> 391.2211 | AC38: IP55 | AD38: IP20 | AE38: Ja | AF38: 2240 | AG38: 1300 | AH38: 250 | AI38: 2050 | AJ38: 168 | AK38: 5 | AN38: 7 modules dubbele kast | AO38: =Y38-Y38/1.21-5*15*M38-4*50 -> -1398.1281
E39: 5 | H39: =I39&" "&" "&J39&" "&M39&" ("&N39&")" -> AlphaESS Storion 192,8 (3 Fase) | I39: AlphaESS | J39: Storion | K39: 24.1 | L39: 8 | M39: =ROUND(K39*L39,2) -> 192.8 | N39: 3 Fase | O39: 0.98 | P39: 8000 | Q39: 8000 | R39: 0.7 | S39: 5 | T39: 30 | U39: 69999 | V39: =U39/1.21 -> 57850.413 | W39: =U39-X39 -> 68999 | X39: 1000 | Y39: =U39-Z39 -> 69999 | AA39: Volwaardig | AB39: =U39/M39 -> 363.06535 | AC39: IP55 | AD39: IP20 | AE39: Ja | AF39: 2240 | AG39: 1300 | AH39: 250 | AI39: 2050 | AJ39: 168 | AK39: 5 | AN39: 8 modules dubbele kast | AO39: =Y39-Y39/1.21-5*15*M39-4*50 -> -2511.4132
E40: 5 | H40: =I40&" "&" "&J40&" "&M40&" ("&N40&")" -> AlphaESS Storion 216,9 (3 Fase) | I40: AlphaESS | J40: Storion | K40: 24.1 | L40: 9 | M40: =ROUND(K40*L40,2) -> 216.9 | N40: 3 Fase | O40: 0.98 | P40: 8000 | Q40: 8000 | R40: 0.7 | S40: 5 | T40: 30 | U40: 73999 | V40: =U40/1.21 -> 61156.198 | W40: =U40-X40 -> 72999 | X40: 1000 | Y40: =U40-Z40 -> 73999 | AA40: Volwaardig | AB40: =U40/M40 -> 341.16644 | AC40: IP55 | AD40: IP20 | AE40: Ja | AF40: 2240 | AG40: 1300 | AH40: 250 | AI40: 2050 | AJ40: 168 | AK40: 5 | AN40: 9 modules dubbele kast | AO40: =Y40-Y40/1.21-5*15*M40-4*50 -> -3624.6983
E41: 5 | H41: =I41&" "&" "&J41&" "&M41&" ("&N41&")" -> AlphaESS Storion 241 (3 Fase) | I41: AlphaESS | J41: Storion | K41: 24.1 | L41: 10 | M41: =ROUND(K41*L41,2) -> 241 | N41: 3 Fase | O41: 0.98 | P41: 8000 | Q41: 8000 | R41: 0.7 | S41: 5 | T41: 30 | U41: 77999 | V41: =U41/1.21 -> 64461.983 | W41: =U41-X41 -> 76999 | X41: 1000 | Y41: =U41-Z41 -> 77999 | AA41: Volwaardig | AB41: =U41/M41 -> 323.6473 | AC41: IP55 | AD41: IP20 | AE41: Ja | AF41: 2240 | AG41: 1300 | AH41: 250 | AI41: 2050 | AJ41: 168 | AK41: 5 | AN41: Grootste Storion opstelling | AO41: =Y41-Y41/1.21-5*15*M41-4*50 -> -4737.9835
B42: 2 | H42: =I42&" "&" "&J42&" "&M42&" ("&N42&")" -> HYXiPOWER HYX Hybride 10,07 (1 Fase) | I42: HYXiPOWER | J42: HYX Hybride | K42: 5.035 | L42: 2 | M42: =ROUND(K42*L42,2) -> 10.07 | N42: 1 Fase | O42: 0.98 | P42: 6000 | Q42: =P42 -> 6000 | R42: 0.7 | S42: 10 | T42: 5 | U42: 8499 | V42: =U42/1.21 -> 7023.9669 | W42: =U42-X42 -> 7499 | X42: 1000 | Y42: =U42-Z42 -> 8499 | AA42: Basis | AB42: =U42/M42 -> 843.99206 | AC42: IP65 | AD42: IP67 | AE42: Ja | AF42: 700 | AG42: 200 | AH42: 350 | AI42: 950 | AJ42: 44 | AK42: 5 | AL42: Alleen Frank | AN42: IP65 = buitengeschikt, 1 fase geen verzwaring nodig, budget optie
B43: 2 | H43: =I43&" "&" "&J43&" "&M43&" ("&N43&")" -> HYXiPOWER HYX Hybride 15,11 (1 Fase) | I43: HYXiPOWER | J43: HYX Hybride | K43: 5.035 | L43: 3 | M43: =ROUND(K43*L43,2) -> 15.11 | N43: 1 Fase | O43: 0.98 | P43: 6000 | Q43: =P43 -> 6000 | R43: 0.7 | S43: 10 | T43: 5 | U43: 9999 | V43: =U43/1.21 -> 8263.6364 | W43: =U43-X43 -> 8999 | X43: 1000 | Y43: =U43-Z43 -> 9999 | AA43: Basis | AB43: =U43/M43 -> 661.74719 | AC43: IP65 | AD43: IP67 | AE43: Ja | AF43: 700 | AG43: 200 | AH43: 350 | AI43: 1300 | AJ43: 44 | AK43: 5 | AL43: Alleen Frank
B44: 2 | H44: =I44&" "&" "&J44&" "&M44&" ("&N44&")" -> HYXiPOWER HYX Hybride 20,14 (1 Fase) | I44: HYXiPOWER | J44: HYX Hybride | K44: 5.035 | L44: 4 | M44: =ROUND(K44*L44,2) -> 20.14 | N44: 1 Fase | O44: 0.98 | P44: 6000 | Q44: 6000 | R44: 0.7 | S44: 10 | T44: 5 | U44: 11499 | V44: =U44/1.21 -> 9503.3058 | W44: =U44-X44 -> 10499 | X44: 1000 | Y44: =U44-Z44 -> 11499 | AA44: Basis | AB44: =U44/M44 -> 570.95333 | AC44: IP65 | AD44: IP67 | AE44: Ja | AF44: 700 | AG44: 200 | AH44: 350 | AI44: 1650 | AJ44: 44 | AK44: 5 | AL44: Alleen Frank
...

Sheet Keuzemenu
C1: Keuze ja/nee
C2: Ja
C3: Nee
D5: kWh per km
C6: Klasse
C7: A - Mini auto | D7: 0.15
C8: B - Compacte auto | D8: 0.2
C9: C - Middenklasse | D9: 0.25
C10: D - Grote auto | D10: 0.3
C11: E - Prestigewagen | D11: 0.4
C12: F - Luxewagens | D12: 0.4
C13: J - Off-road sportwagens | D13: 0.5
I16: Handel
C17: soort contract | H17: Start | I17: =IF(Calculator!P114<>"Alleen Zelfconsumptie","Ja","Nee") -> Ja
C18: Vast | H18: Toekomst | I18: =IF(Calculator!P116<>"Alleen Zelfconsumptie","Ja","Nee") -> Ja
C19: Variabel
C20: Dynamisch
C23: Leverancier | D23: opslag laag | E23: opslag terugl | F23: Extra rendement
C24: Frank Energie | D24: 0.02 | E24: 0 | F24: 0
C25: Hegg Energy | D25: 0.034 | E25: 0.034 | F25: 0.04
C26: Next Energy | D26: 0.02 | E26: 0 | F26: 0
R27: =Calculator!P114 -> Actief handelen | T27: =Calculator!P116 -> Actief handelen
D28: omvormer | E28: omvormer | F28: omvormer | G28: omvormer | H28: omvormer | I28: omvormer | J28: omvormer | K28: omvormer | L28: omvormer | M28: omvormer | N28: omvormer | O28: omvormer | P28: omvormer | R28: omvormer | T28: omvormer
D29: 5 | E29: 6 | F29: 8 | G29: 10 | H29: 11 | I29: 13 | J29: 20 | K29: 30 | L29: 40 | M29: 50 | N29: 60 | O29: 70 | P29: 80 | R29: =Calculator!R102 -> 10 | T29: =R29 -> 10
C30: Cycli per dag | D30: 2 | E30: =D30+1 -> 3 | F30: =E30+1 -> 4 | G30: =F30+1 -> 5 | H30: =G30+1 -> 6 | I30: =H30+1 -> 7 | J30: =I30+1 -> 8 | K30: =J30+1 -> 9 | L30: =K30+1 -> 10 | ... P30: =O30+1 -> 14 | R30: =HLOOKUP(R29,D29:P30,2,FALSE) -> 5 | T30: =HLOOKUP(T29,D29:P30,2,FALSE) -> 5
C31: Alleen zelfconsumptie | D31: 1 | E31: 1 | F31: 1 | G31: 1 | H31: 1 | I31: 1 | J31: =I31+0.2 -> 1.2 | K31: =J31+0.05 -> 1.25 | L31: 1 | M31: =K31+0.1 -> 1.35 | N31: 1 | O31: 1 | P31: 1 | R31: =VLOOKUP(R27,C31:P33,R30,FALSE) -> 1.5 | T31: =VLOOKUP(T27,C31:P33,T30,FALSE) -> 1.5
C32: Zelfconsumptie + Handel | D32: 1.25 | E32: 1.25 | F32: 1.25 | G32: 1.25 | H32: 1.25 | I32: 1.25 | J32: =I32+0.2 -> 1.45 | K32: =J32+0.05 -> 1.5 | L32: 1.25 | M32: =K32+0.1 -> 1.6 | N32: 1.25 | O32: 1.25 | P32: 1.25
C33: Actief handelen | D33: 1.5 | E33: 1.5 | F33: 1.5 | G33: 1.5 | H33: 1.5 | I33: 1.5 | J33: =I33+0.2 -> 1.7 | K33: =J33+0.05 -> 1.75 | L33: 1.5 | M33: =K33+0.1 -> 1.85 | N33: 1.5 | O33: 1.5 | P33: 1.5
C36: BTW
C37: Ja, particulier nieuw in KOR
C38: Ja, particulier al in KOR
C39: Ja, zakelijk
C40: Nee
C42: Particulier of zakelijk
C43: Particulier
C44: Zakelijk

Sheet Stamgegevens
A1: 1 | B1: =A1+1 -> 2 | C1: =B1+1 -> 3 | D1: =C1+1 -> 4 | E1: =D1+1 -> 5 | F1: =E1+1 -> 6 | G1: =F1+1 -> 7 | H1: =G1+1 -> 8 | I1: =H1+1 -> 9 | ... AE1: =AD1+1 -> 31
A2: Stamgegevens | D2: handmatige invoer | G2: zelfde als vorig jaar | K2: zelfde als vorig jaar + inflatie/aanpassing | Q2: Laatste jaar saldering | R2: 2026
S4: excl. eb. | T4: excl. eb. | Y4: correctie
D5: maximale | E5: af te dragen | F5: af te dragen | J5: energie | L5: energie | P5: vastrecht | Q5: vastrecht | S5: leverings | T5: leverings | W5: omreken | Y5: tarief | AA5: effectieve | AC5: correctie | AE5: uit
C6: BTW-% | D6: BTW | E6: BTW | F6: BTW | H6: jaarlijkse | J6: belasting | K6: vanaf | L6: belasting | M6: jaarlijkse | N6: percentage | P6: stroom | Q6: gas | S6: kosten | T6: kosten | W6: factor | Y6: terug | AA6: minuten | AC6: tarief | AE6: betalings
A7: jaar | C7: batterijen | D7: teruggave | E7: per kWh | F7: per 1000 Wp | H7: inflatie | J7: incl BTW | K7: KwH | L7: incl BTW | M7: aanpassing | N7: saldering | P7: nieuw | Q7: nieuw | S7: laag | T7: hoog | W7: gas | Y7: levering | AA7: per kwartier | AC7: handel | AE7: %
A8: 2025 | C8: 0.21 | D8: 2494 | E8: 15 | F8: 20 | H8: 0.032 | J8: 0.12286 | K8: 10000 | L8: 0.08394 | M8: 0 | N8: 1 | P8: 5.99 | Q8: 5.99 | S8: 0.01 | T8: 0.15 | W8: 3.5 | Y8: -0.02 | AA8: 14 | AC8: =IF(Calculator!R112<>"Next Energy",0.2,0.24) -> 0.2 | AE8: 0.85
A9: =A8+1 -> 2026 | C9: =C8 -> 0.21 | D9: =D8 -> 2494 | E9: =E8 -> 15 | F9: =F8 -> 20 | H9: 0.028 | J9: 0.11046 | K9: =K8 -> 10000 | L9: =L8*(1+M8) -> 0.08394 | M9: 0 | N9: 1 | P9: =P8*(1+H8) -> 6.18168 | Q9: =Q8*(1+H8) -> 6.18168 | S9: =S8*(1+H8) -> 0.01032 | T9: =T8*(1+H8) -> 0.1548 | W9: =W8 -> 3.5 | Y9: =Y8 -> -0.02 | AA9: =AA8 -> 14 | AC9: =AC8 -> 0.2 | AE9: =AE8 -> 0.85
A10: =A9+1 -> 2027 | C10: =C9 -> 0.21 | D10: =D9 -> 2494 | E10: =E9 -> 15 | F10: =F9 -> 20 | H10: 0.025 | J10: =J9*(1+M9) -> 0.11046 | K10: =K9 -> 10000 | L10: =L9*(1+M9) -> 0.08394 | M10: 0 | N10: 0 | P10: =P9*(1+H9) -> 6.354767 | Q10: =Q9*(1+H9) -> 6.354767 | S10: =S9*(1+H9) -> 0.01060896 | T10: =T9*(1+H9) -> 0.1591344 | W10: =W9 -> 3.5 | Y10: =Y9 -> -0.02 | AA10: =AA9 -> 14 | AC10: =AC9 -> 0.2 | AE10: =AE9 -> 0.85
A11: =A10+1 -> 2028 | C11: =C10 -> 0.21 | D11: =D10 -> 2494 | E11: =E10 -> 15 | F11: =F10 -> 20 | H11: =H10 -> 0.025 | J11: =J10*(1+M10) -> 0.11046 | K11: =K10 -> 10000 | L11: =L10*(1+M10) -> 0.08394 | M11: =M10 -> 0 | N11: =N10 -> 0 | P11: =P10*(1+H10) -> 6.5136362 | Q11: =Q10*(1+H10) -> 6.5136362 | S11: =S10*(1+H10) -> 0.010874184 | T11: =T10*(1+H10) -> 0.16311276 | W11: =W10 -> 3.5 | Y11: =Y10 -> -0.02 | AA11: =AA10 -> 14 | AC11: =AC10 -> 0.2 | AE11: =AE10 -> 0.85
A12: =A11+1 -> 2029 | C12: =C11 -> 0.21 | D12: =D11 -> 2494 | E12: =E11 -> 15 | F12: =F11 -> 20 | H12: =H11 -> 0.025 | J12: =J11*(1+M11) -> 0.11046 | K12: =K11 -> 10000 | L12: =L11*(1+M11) -> 0.08394 | M12: =M11 -> 0 | N12: =N11 -> 0 | P12: =P11*(1+H11) -> 6.6764771 | Q12: =Q11*(1+H11) -> 6.6764771 | S12: =S11*(1+H11) -> 0.011146039 | T12: =T11*(1+H11) -> 0.16719058 | W12: =W11 -> 3.5 | Y12: =Y11 -> -0.02 | AA12: =AA11 -> 14 | AC12: =AC11 -> 0.2 | AE12: =AE11 -> 0.85
A13: =A12+1 -> 2030 | C13: =C12 -> 0.21 | D13: =D12 -> 2494 | E13: =E12 -> 15 | F13: =F12 -> 20 | H13: =H12 -> 0.025 | J13: =J12*(1+M12) -> 0.11046 | K13: =K12 -> 10000 | L13: =L12*(1+M12) -> 0.08394 | M13: =M12 -> 0 | N13: =N12 -> 0 | P13: =P12*(1+H12) -> 6.843389 | Q13: =Q12*(1+H12) -> 6.843389 | S13: =S12*(1+H12) -> 0.01142469 | T13: =T12*(1+H12) -> 0.17137034 | W13: =W12 -> 3.5 | Y13: =Y12 -> -0.02 | AA13: =AA12 -> 14 | AC13: =AC12 -> 0.2 | AE13: =AE12 -> 0.85
A14: =A13+1 -> 2031 | C14: =C13 -> 0.21 | D14: =D13 -> 2494 | E14: =E13 -> 15 | F14: =F13 -> 20 | H14: =H13 -> 0.025 | J14: =J13*(1+M13) -> 0.11046 | K14: =K13 -> 10000 | L14: =L13*(1+M13) -> 0.08394 | M14: =M13 -> 0 | N14: =N13 -> 0 | P14: =P13*(1+H13) -> 7.0144738 | Q14: =Q13*(1+H13) -> 7.0144738 | S14: =S13*(1+H13) -> 0.011710307 | T14: =T13*(1+H13) -> 0.1756546 | W14: =W13 -> 3.5 | Y14: =Y13 -> -0.02 | AA14: =AA13 -> 14 | AC14: =AC13 -> 0.2 | AE14: =AE13 -> 0.85
A15: =A14+1 -> 2032 | C15: =C14 -> 0.21 | D15: =D14 -> 2494 | E15: =E14 -> 15 | F15: =F14 -> 20 | H15: =H14 -> 0.025 | J15: =J14*(1+M14) -> 0.11046 | K15: =K14 -> 10000 | L15: =L14*(1+M14) -> 0.08394 | M15: =M14 -> 0 | N15: =N14 -> 0 | P15: =P14*(1+H14) -> 7.1898356 | Q15: =Q14*(1+H14) -> 7.1898356 | S15: =S14*(1+H14) -> 0.012003064 | T15: =T14*(1+H14) -> 0.18004597 | W15: =W14 -> 3.5 | Y15: =Y14 -> -0.02 | AA15: =AA14 -> 14 | AC15: =AC14 -> 0.2 | AE15: =AE14 -> 0.85
A16: =A15+1 -> 2033 | C16: =C15 -> 0.21 | D16: =D15 -> 2494 | E16: =E15 -> 15 | F16: =F15 -> 20 | H16: =H15 -> 0.025 | J16: =J15*(1+M15) -> 0.11046 | K16: =K15 -> 10000 | L16: =L15*(1+M15) -> 0.08394 | M16: =M15 -> 0 | N16: =N15 -> 0 | P16: =P15*(1+H15) -> 7.3695815 | Q16: =Q15*(1+H15) -> 7.3695815 | S16: =S15*(1+H15) -> 0.012303141 | T16: =T15*(1+H15) -> 0.18454712 | W16: =W15 -> 3.5 | Y16: =Y15 -> -0.02 | AA16: =AA15 -> 14 | AC16: =AC15 -> 0.2 | AE16: =AE15 -> 0.85
A17: =A16+1 -> 2034 | C17: =C16 -> 0.21 | D17: =D16 -> 2494 | E17: =E16 -> 15 | F17: =F16 -> 20 | H17: =H16 -> 0.025 | J17: =J16*(1+M16) -> 0.11046 | K17: =K16 -> 10000 | L17: =L16*(1+M16) -> 0.08394 | M17: =M16 -> 0 | N17: =N16 -> 0 | P17: =P16*(1+H16) -> 7.553821 | Q17: =Q16*(1+H16) -> 7.553821 | S17: =S16*(1+H16) -> 0.01261072 | T17: =T16*(1+H16) -> 0.18916079 | W17: =W16 -> 3.5 | Y17: =Y16 -> -0.02 | AA17: =AA16 -> 14 | AC17: =AC16 -> 0.2 | AE17: =AE16 -> 0.85
A18: =A17+1 -> 2035 | C18: =C17 -> 0.21 | D18: =D17 -> 2494 | E18: =E17 -> 15 | F18: =F17 -> 20 | H18: =H17 -> 0.025 | J18: =J17*(1+M17) -> 0.11046 | K18: =K17 -> 10000 | L18: =L17*(1+M17) -> 0.08394 | M18: =M17 -> 0 | N18: =N17 -> 0 | P18: =P17*(1+H17) -> 7.7426666 | Q18: =Q17*(1+H17) -> 7.7426666 | S18: =S17*(1+H17) -> 0.012925988 | T18: =T17*(1+H17) -> 0.19388981 | W18: =W17 -> 3.5 | Y18: =Y17 -> -0.02 | AA18: =AA17 -> 14 | AC18: =AC17 -> 0.2 | AE18: =AE17 -> 0.85
A19: =A18+1 -> 2036 | C19: =C18 -> 0.21 | D19: =D18 -> 2494 | E19: =E18 -> 15 | F19: =F18 -> 20 | H19: =H18 -> 0.025 | J19: =J18*(1+M18) -> 0.11046 | K19: =K18 -> 10000 | L19: =L18*(1+M18) -> 0.08394 | M19: =M18 -> 0 | N19: =N18 -> 0 | P19: =P18*(1+H18) -> 7.9362332 | Q19: =Q18*(1+H18) -> 7.9362332 | S19: =S18*(1+H18) -> 0.013249137 | T19: =T18*(1+H18) -> 0.19873706 | W19: =W18 -> 3.5 | Y19: =Y18 -> -0.02 | AA19: =AA18 -> 14 | AC19: =AC18 -> 0.2 | AE19: =AE18 -> 0.85
A20: =A19+1 -> 2037 | C20: =C19 -> 0.21 | D20: =D19 -> 2494 | E20: =E19 -> 15 | F20: =F19 -> 20 | H20: =H19 -> 0.025 | J20: =J19*(1+M19) -> 0.11046 | K20: =K19 -> 10000 | L20: =L19*(1+M19) -> 0.08394 | M20: =M19 -> 0 | N20: =N19 -> 0 | P20: =P19*(1+H19) -> 8.1346391 | Q20: =Q19*(1+H19) -> 8.1346391 | S20: =S19*(1+H19) -> 0.013580366 | T20: =T19*(1+H19) -> 0.20370549 | W20: =W19 -> 3.5 | Y20: =Y19 -> -0.02 | AA20: =AA19 -> 14 | AC20: =AC19 -> 0.2 | AE20: =AE19 -> 0.85
A21: =A20+1 -> 2038 | C21: =C20 -> 0.21 | D21: =D20 -> 2494 | E21: =E20 -> 15 | F21: =F20 -> 20 | H21: =H20 -> 0.025 | J21: =J20*(1+M20) -> 0.11046 | K21: =K20 -> 10000 | L21: =L20*(1+M20) -> 0.08394 | M21: =M20 -> 0 | N21: =N20 -> 0 | P21: =P20*(1+H20) -> 8.338005 | Q21: =Q20*(1+H20) -> 8.338005 | S21: =S20*(1+H20) -> 0.013919875 | T21: =T20*(1+H20) -> 0.20879812 | W21: =W20 -> 3.5 | Y21: =Y20 -> -0.02 | AA21: =AA20 -> 14 | AC21: =AC20 -> 0.2 | AE21: =AE20 -> 0.85
A22: =A21+1 -> 2039 | C22: =C21 -> 0.21 | D22: =D21 -> 2494 | E22: =E21 -> 15 | F22: =F21 -> 20 | H22: =H21 -> 0.025 | J22: =J21*(1+M21) -> 0.11046 | K22: =K21 -> 10000 | L22: =L21*(1+M21) -> 0.08394 | M22: =M21 -> 0 | N22: =N21 -> 0 | P22: =P21*(1+H21) -> 8.5464552 | Q22: =Q21*(1+H21) -> 8.5464552 | S22: =S21*(1+H21) -> 0.014267872 | T22: =T21*(1+H21) -> 0.21401808 | W22: =W21 -> 3.5 | Y22: =Y21 -> -0.02 | AA22: =AA21 -> 14 | AC22: =AC21 -> 0.2 | AE22: =AE21 -> 0.85
... A36: =A35+1 -> 2053 | C36: =C35 -> 0.21 | D36: =D35 -> 2494 | E36: =E35 -> 15 | F36: =F35 -> 20 | H36: =H35 -> 0.025 | J36: =J35*(1+M35) -> 0.11046 | K36: =K35 -> 10000 | L36: =L35*(1+M35) -> 0.08394 | M36: =M35 -> 0 | N36: =N35 -> 0 | P36: =P35*(1+H35) -> 12.075917 | Q36: =Q35*(1+H35) -> 12.075917 | S36: =S35*(1+H35) -> 0.020160129 | T36: =T35*(1+H35) -> 0.30240194 | W36: =W35 -> 3.5 | Y36: =Y35 -> -0.02 | AA36: =AA35 -> 14 | AC36: =AC35 -> 0.2 | AE36: =AE35 -> 0.85
AC39: Ik heb AB7 aangepast ivm geen opslag next

Sheet BTW
C3: BTW-percentage batterijen | D3: =IF(D13="nee",0,VLOOKUP(Jaargegevens!$E$5,Stamgegevens!$A$8:$AE$36,Stamgegevens!$C$1)) -> 0.21 | E3: =IF(D3=0,0,D3/(1+D3)) -> 0.17355372 | H3: Geen BTW | J3: Geen teruggave BTW op aanschaf batterijen.
C5: factuur en btw-bedrag particulier | D5: =VLOOKUP(Calculator!M90,Producten!$H$7:$AA$1007,18,FALSE) -> 13999 | E5: =ROUND(D5*E3,0) -> 2430 | H5: BTW particulier maximaal | J5: =CONCATENATE("Maximaal € ",E9,CONCATENATE(" minus € ",E11," per kWh capaciteit (€ ",D21,").")) -> Maximaal € 2494 minus € 15 per kWh capaciteit (€ 328).
J6: =IF(D26=0,"","1e jaar : ") | K6: =IF(H26=0,"","1e jaar : ") -> 1e jaar : | T6: Calculator
C7: factuur en btw-bedrag zakelijk | D7: =Calculator!R125+Calculator!R127 -> 14999 | E7: =ROUND(D7*E3,0) -> 2603 | H7: BTW particulier alles | J7: =CONCATENATE("€ ",D19,CONCATENATE(" minus € ",E11," per kWh capaciteit (€ ",D21,").")) -> € 2430 minus € 15 per kWh capaciteit (€ 328). | T7: Klant | U7: BTW | V7: KOR | W7: KEY
T8: =Calculator!R137 -> Particulier | U8: =Calculator!R139 -> Ja | V8: =Calculator!R141 -> Nee | W8: =T8&U8&V8 -> ParticulierJaNee | X8: 0
C9: maximale BTW-teruggave | D9: =VLOOKUP(Jaargegevens!$E$5,Stamgegevens!$A$8:$AE$36,Stamgegevens!$D$1) -> 2494 | E9: =IF(D3=0,0,D9) -> 2494 | H9: BTW zakelijk geen KOR | J9: =CONCATENATE("1e jaar : € ",L19," minus af te dragen BTW teruglevering € ",L21," (schatting).") -> 1e jaar : € 2603 minus af te dragen BTW teruglevering € 328 (schatting).
T10: Teruggave | V10: =IF(T8="Zakelijk",Calculator!S144,IF(D38<0,0,Calculator!S144)) -> 2102
C11: af te dragen BTW per kWh | D11: =VLOOKUP(Jaargegevens!$E$5,Stamgegevens!$A$8:$AE$36,Stamgegevens!$E$1) -> 15 | E11: =IF(D3=0,0,D11) -> 15 | H11: BTW zakelijk KOR | J11: =CONCATENATE("1e jaar : € ",H19," minus af te dragen BTW teruglevering € ",O21," (schatting).") -> 1e jaar : € 2430 minus af te dragen BTW teruglevering € 328 (schatting). | T11: Kosten | V11: =IF(T8="Zakelijk",L21,IF(D38<0,0,SUM(D21:D22)+D29)) -> 378 | W11: Eind jaar | X11: =VLOOKUP(W8,W27:X34,2,FALSE)+Kosten!B6 -> 2025
T12: Per saldo | V12: =Kosten!J29 -> 2102
C13: BTW-teruggave | D13: =IF(T8="Zakelijk","ja",IF(Calculator!P114="Alleen zelfconsumptie","nee","ja")) -> ja | T13: De eenmalige investering voor de klant, inclusief teruggave BTW.
D16: particulier | H16: particulier/zakelijk | L16: zakelijk | O16: zakelijk | T16: Klant | U16: BTW | V16: KOR | W16: KEY
D17: nieuw | H17: nu in KOR | L17: niet in KOR | O17: wel in KOR | T17: Particulier | U17: Ja | V17: Nee | W17: =T17&U17&V17 -> ParticulierJaNee | X17: =D23 -> 2102
T18: Particulier | U18: Ja | V18: Ja | W18: =T18&U18&V18 -> ParticulierJaJa | X18: =H23 -> 2102
A19: BTW terug te ontvangen | D19: =E5 -> 2430 | H19: =E5 -> 2430 | L19: =E7 -> 2603 | O19: =L19 -> 2603 | T19: Particulier | U19: Nee | V19: Nee | W19: =T19&U19&V19 -> ParticulierNeeNee | X19: 0
T20: Particulier | U20: Nee | V20: Ja | W20: =T20&U20&V20 -> ParticulierNeeJa | X20: 0
A21: af te dragen batterij | C21: =Calculator!R92 -> 21.85 | D21: =ROUND(C21*E11,0) -> 328 | H21: =D21 -> 328 | L21: =H21 -> 328 | O21: =L21 -> 328 | T21: Zakelijk | U21: Ja | V21: Ja | W21: =T21&U21&V21 -> ZakelijkJaJa | X21: =H23 -> 2102
D22: - | H22: - | L22: - | O22: - | T22: Zakelijk | U22: Ja | V22: Nee | W22: =T22&U22&V22 -> ZakelijkJaNee | X22: =L23 -> 2275
A23: per saldo te ontvangen | D23: =D19-D21 -> 2102 | H23: =H19-H21 -> 2102 | L23: =L19-L21 -> 2275 | O23: =O19-O21 -> 2275 | T23: Zakelijk | U23: Nee | V23: Nee | W23: =T23&U23&V23 -> ZakelijkNeeNee | X23: 0
D24: = | H24: = | L24: = | O24: = | T24: Zakelijk | U24: Nee | V24: Ja | W24: =T24&U24&V24 -> ZakelijkNeeJa | X24: 0
A26: aantal jaren te betalen | D26: =IF(E5>E9,4,0) -> 0 | H26: =IF(D13="nee",0,IF(E5>E9,4,1)) -> 1 | L26: 19 | O26: =IF(E5>E9,4,1) -> 1 | T26: Klant | U26: BTW | V26: KOR | W26: KEY
D27: = | H27: = | L27: = | O27: = | T27: Particulier | U27: Ja | V27: Nee | W27: =T27&U27&V27 -> ParticulierJaNee | X27: =D26 -> 0
T28: Particulier | U28: Ja | V28: Ja | W28: =T28&U28&V28 -> ParticulierJaJa | X28: =H26 -> 1
A29: Kosten aangifte | D29: 50 | H29: 50 | L29: 0 | O29: 0 | T29: Particulier | U29: Nee | V29: Nee | W29: =T29&U29&V29 -> ParticulierNeeNee | X29: 0
D30: = | H30: = | L30: = | O30: = | T30: Particulier | U30: Nee | V30: Ja | W30: =T30&U30&V30 -> ParticulierNeeJa | X30: 0
T31: Zakelijk | U31: Ja | V31: Ja | W31: =T31&U31&V31 -> ZakelijkJaJa | X31: =H26 -> 1
B32: Aanpassingen | T32: Zakelijk | U32: Ja | V32: Nee | W32: =T32&U32&V32 -> ZakelijkJaNee | X32: =L26 -> 19
B33: Producten kolom P bedrag gebruiken voor BTW berekening | T33: Zakelijk | U33: Nee | V33: Nee | W33: =T33&U33&V33 -> ZakelijkNeeNee | X33: 0
B34: Als BTW is groter dan 2494 dan 5 jaar 15 euro per kWh | T34: Zakelijk | U34: Nee | V34: Ja | W34: =T34&U34&V34 -> ZakelijkNeeJa | X34: 0
B35: Als BTW is kleiner dan 2495 dan 1 jaar 15 euro per kWh
B38: Totaal | D38: =D23-D26*(D21+D29) -> 2102 | H38: =H23-H26*(H21+H29) -> 1724 | L38: =L23-L26*(L21+L29) -> -3957 | O38: =O23-O26*(O21+O29) -> 1947
D39: = | H39: = | L39: = | O39: =
D41: =IF(D38<0,"nadeel ! ","voordeel ") -> voordeel | H41: =IF(H38<0,"nadeel ! ","voordeel ") -> voordeel | L41: =IF(L38<0,"nadeel ! ","voordeel ") -> nadeel ! | O41: =IF(O38<0,"nadeel ! ","voordeel ") -> voordeel
B44: Klant | C44: BTW | D44: KOR | S44: rgl | T44: Klant | U44: BTW | V44: KOR | W44: KEY
A45: rg1 | B45: =IF(ISERROR(VLOOKUP($A45,INDIRECT($W$8),2,FALSE)),"?",VLOOKUP($A45,INDIRECT($W$8),2,FALSE)) -> Particulier | C45: =IF(ISERROR(VLOOKUP($A45,INDIRECT($W$8),3,FALSE)),"?",VLOOKUP($A45,INDIRECT($W$8),3,FALSE)) -> Ja | D45: =IF(ISERROR(VLOOKUP($A45,INDIRECT($W$8),4,FALSE)),"?",VLOOKUP($A45,INDIRECT($W$8),4,FALSE)) -> Nee | E45: =IF(ISERROR(VLOOKUP($A45,INDIRECT($W$8),6,FALSE)),"?",VLOOKUP($A45,INDIRECT($W$8),6,FALSE)) -> € 2430 minus € 15 per kWh capaciteit (€ 328). | S45: rg1 | T45: Particulier | U45: Ja | V45: Nee | W45: =T45&U45&V45 -> ParticulierJaNee | X45: =IF(D13="nee","Geen teruggave BTW op aanschaf batterijen",CONCATENATE(J6,IF(D19=E9,J5,J7))) -> € 2430 minus € 15 per kWh capaciteit (€ 328).
A46: rg2 | B46: =IF(ISERROR(VLOOKUP($A46,INDIRECT($W$8),2,FALSE)),"?",VLOOKUP($A46,INDIRECT($W$8),2,FALSE)) -> Particulier | C46: =IF(ISERROR(VLOOKUP($A46,INDIRECT($W$8),3,FALSE)),"?",VLOOKUP($A46,INDIRECT($W$8),3,FALSE)) -> Ja | D46: =IF(ISERROR(VLOOKUP($A46,INDIRECT($W$8),4,FALSE)),"?",VLOOKUP($A46,INDIRECT($W$8),4,FALSE)) -> Nee | E46: =IF(ISERROR(VLOOKUP($A46,INDIRECT($W$8),6,FALSE)),"?",VLOOKUP($A46,INDIRECT($W$8),6,FALSE)) | S46: rg2 | T46: Particulier | U46: Ja | V46: Nee | W46: =T46&U46&V46 -> ParticulierJaNee | X46: =IF(D26=0,"",CONCATENATE("Daarna nog ",D26," jaar € ",D21," af te dragen BTW."))
A47: rg3 | B47: =IF(ISERROR(VLOOKUP($A47,INDIRECT($W$8),2,FALSE)),"?",VLOOKUP($A47,INDIRECT($W$8),2,FALSE)) -> Particulier | C47: =IF(ISERROR(VLOOKUP($A47,INDIRECT($W$8),3,FALSE)),"?",VLOOKUP($A47,INDIRECT($W$8),3,FALSE)) -> Ja | D47: =IF(ISERROR(VLOOKUP($A47,INDIRECT($W$8),4,FALSE)),"?",VLOOKUP($A47,INDIRECT($W$8),4,FALSE)) -> Nee | E47: =IF(ISERROR(VLOOKUP($A47,INDIRECT($W$8),6,FALSE)),"?",VLOOKUP($A47,INDIRECT($W$8),6,FALSE)) | S47: rg3 | T47: Particulier | U47: Ja | V47: Nee | W47: =T47&U47&V47 -> ParticulierJaNee | X47: =IF(D26=0,"",CONCATENATE("Jaarlijkse kosten BTW-aangifte € ",D29))
A48: rg4 | B48: =IF(ISERROR(VLOOKUP($A48,INDIRECT($W$8),2,FALSE)),"?",VLOOKUP($A48,INDIRECT($W$8),2,FALSE)) -> Particulier | C48: =IF(ISERROR(VLOOKUP($A48,INDIRECT($W$8),3,FALSE)),"?",VLOOKUP($A48,INDIRECT($W$8),3,FALSE)) -> Ja | D48: =IF(ISERROR(VLOOKUP($A48,INDIRECT($W$8),4,FALSE)),"?",VLOOKUP($A48,INDIRECT($W$8),4,FALSE)) -> Nee | E48: =IF(ISERROR(VLOOKUP($A48,INDIRECT($W$8),6,FALSE)),"?",VLOOKUP($A48,INDIRECT($W$8),6,FALSE)) | S48: rg4 | T48: Particulier | U48: Ja | V48: Nee | W48: =T48&U48&V48 -> ParticulierJaNee | X48: =IF(D26=0,"",CONCATENATE("Totaal BTW-",D41,"per saldo € ",D38))
A49: rg5 | B49: =IF(ISERROR(VLOOKUP($A49,INDIRECT($W$8),2,FALSE)),"?",VLOOKUP($A49,INDIRECT($W$8),2,FALSE)) -> Particulier | C49: =IF(ISERROR(VLOOKUP($A49,INDIRECT($W$8),3,FALSE)),"?",VLOOKUP($A49,INDIRECT($W$8),3,FALSE)) -> Ja | D49: =IF(ISERROR(VLOOKUP($A49,INDIRECT($W$8),4,FALSE)),"?",VLOOKUP($A49,INDIRECT($W$8),4,FALSE)) -> Nee | E49: =IF(ISERROR(VLOOKUP($A49,INDIRECT($W$8),6,FALSE)),"?",VLOOKUP($A49,INDIRECT($W$8),6,FALSE)) | S49: rg5 | T49: Particulier | U49: Ja | V49: Nee | W49: =T49&U49&V49 -> ParticulierJaNee
A50: rg6 | B50: =IF(ISERROR(VLOOKUP($A50,INDIRECT($W$8),2,FALSE)),"?",VLOOKUP($A50,INDIRECT($W$8),2,FALSE)) -> Particulier | C50: =IF(ISERROR(VLOOKUP($A50,INDIRECT($W$8),3,FALSE)),"?",VLOOKUP($A50,INDIRECT($W$8),3,FALSE)) -> Ja | D50: =IF(ISERROR(VLOOKUP($A50,INDIRECT($W$8),4,FALSE)),"?",VLOOKUP($A50,INDIRECT($W$8),4,FALSE)) -> Nee | E50: =IF(ISERROR(VLOOKUP($A50,INDIRECT($W$8),6,FALSE)),"?",VLOOKUP($A50,INDIRECT($W$8),6,FALSE)) | S50: rg6 | T50: Particulier | U50: Ja | V50: Nee | W50: =T50&U50&V50 -> ParticulierJaNee | X50: =IF(D38<0,"In de berekening van de kosten wordt ervan uitgegaan, dat er","")
A51: rg7 | B51: =IF(ISERROR(VLOOKUP($A51,INDIRECT($W$8),2,FALSE)),"?",VLOOKUP($A51,INDIRECT($W$8),2,FALSE)) -> Particulier | C51: =IF(ISERROR(VLOOKUP($A51,INDIRECT($W$8),3,FALSE)),"?",VLOOKUP($A51,INDIRECT($W$8),3,FALSE)) -> Ja | D51: =IF(ISERROR(VLOOKUP($A51,INDIRECT($W$8),4,FALSE)),"?",VLOOKUP($A51,INDIRECT($W$8),4,FALSE)) -> Nee | E51: =IF(ISERROR(VLOOKUP($A51,INDIRECT($W$8),6,FALSE)),"?",VLOOKUP($A51,INDIRECT($W$8),6,FALSE)) | S51: rg7 | T51: Particulier | U51: Ja | V51: Nee | W51: =T51&U51&V51 -> ParticulierJaNee | X51: =IF(D38<0,"geen BTW teruggevraagd wordt, omdat dit geen voordeel oplevert","")
...

Sheet Jaargegevens
L2: datum van gas af | M2: =IF(ISNUMBER(Calculator!R77),Calculator!R77,E3) -> 54789
D3: startdatum | E3: =IF(ISNUMBER(Calculator!R110),Calculator!R110,NOW()) -> 45992 | F3: =MONTH(E3)+1 -> 13 | L3: dagen tot van gas af | M3: =IF(M2<E3,0,M2-E3) -> 8797 | O3: =IF(M3=0,"al van gas af bij installatie batterijen", "")
D5: vanaf jaar | E5: =YEAR(E3) -> 2025 | L5: huidig contract dynamisch | M5: =IF(Calculator!R25<>"Dynamisch","nee","ja") -> nee
D7: verdeling jaar | E7: =Opbrengsten!C5 -> 0.084931507 | F7: =1-E7 -> 0.91506849 | L7: laatste jaar saldering | M7: =IF(M5="nee",Stamgegevens!R2,0) -> 2026
L9: energiebelasting dit jaar | M9: =VLOOKUP($A14,Stamgegevens!$A$8:$AE$36,Stamgegevens!$J$1) -> 0.12286
O10: excl. en.bel. | P10: excl. en.bel. | R10: handel | Z10: correctie
F11: energie | H11: energie | J11: energie | L11: vastrecht | M11: vastrecht | O11: leverings | P11: opslag | Q11: leverings | R11: leverings | S11: opslag | U11: dagen | V11: dagen | X11: omreken | Z11: tarief | AB11: effectieve | AD11: correctie | AF11: uit
D12: jaarlijkse | F12: belasting | G12: vanaf | H12: belasting | I12: percentage | J12: belasting | L12: stroom | M12: gas | O12: kosten | P12: kosten | Q12: kosten | R12: kosten | S12: terug | U12: tot van | V12: tot | X12: factor | Z12: terug | AB12: minuten | AD12: tarief | AF12: betalings
A13: jaar 1 | D13: inflatie | F13: incl BTW | G13: KwH | H13: incl BTW | I13: saldering | J13: na saldering | L13: nieuw | M13: nieuw | O13: laag | P13: laag | Q13: hoog | R13: hoog | S13: levering | U13: gas af | V13: el. auto | X13: gas | Z13: levering | AB13: per kwartier | AD13: handel | AF13: %
A14: =E5 -> 2025 | B14: 1 | D14: =VLOOKUP($A14,Stamgegevens!$A$8:$AE$36,Stamgegevens!$H$1) -> 0.032 | F14: =VLOOKUP($A14,Stamgegevens!$A$8:$AE$36,Stamgegevens!$J$1) -> 0.12286 | G14: =VLOOKUP($A14,Stamgegevens!$A$8:$AE$36,Stamgegevens!$K$1) -> 10000 | H14: =VLOOKUP($A14,Stamgegevens!$A$8:$AE$36,Stamgegevens!$L$1) -> 0.08394 | I14: =VLOOKUP($A14,Stamgegevens!$A$8:$AE$36,Stamgegevens!$N$1) -> 1 | J14: =F14*I14 -> 0.12286 | L14: =VLOOKUP($A14,Stamgegevens!$A$8:$AE$36,Stamgegevens!$P$1) -> 5.99 | M14: =VLOOKUP($A14,Stamgegevens!$A$8:$AE$36,Stamgegevens!$Q$1) -> 5.99 | O14: =VLOOKUP($A14,Stamgegevens!$A$8:$AE$36,Stamgegevens!$S$1) -> 0.01 | P14: =VLOOKUP(Calculator!R112,Keuzemenu!C24:E26,2) -> 0.02 | Q14: =VLOOKUP($A14,Stamgegevens!$A$8:$AE$36,Stamgegevens!$U$1) -> 0 | R14: =VLOOKUP($A14,Stamgegevens!$A$8:$AE$36,Stamgegevens!$T$1) -> 0.15 | S14: =VLOOKUP(Calculator!R112,Keuzemenu!C24:E26,3) -> 0 | U14: =IF($M$3=0,$M$3,$M$3-365*$E$7) -> 8766 | X14: =VLOOKUP($A14,Stamgegevens!$A$8:$AE$36,Stamgegevens!$W$1) -> 3.5 | Z14: =VLOOKUP($A14,Stamgegevens!$A$8:$AE$36,Stamgegevens!$Y$1) -> -0.02 | AB14: =VLOOKUP($A14,Stamgegevens!$A$8:$AE$36,Stamgegevens!$AA$1) -> 14 | AD14: =VLOOKUP($A14,Stamgegevens!$A$8:$AE$36,Stamgegevens!$AC$1) -> 0.2 | AF14: =VLOOKUP($A14,Stamgegevens!$A$8:$AE$36,Stamgegevens!$AE$1) -> 0.85
A15: =A14+1 -> 2026 | B15: 2 | D15: =VLOOKUP($A15,Stamgegevens!$A$8:$AE$36,Stamgegevens!$H$1) -> 0.028 | F15: =VLOOKUP($A15,Stamgegevens!$A$8:$AE$36,Stamgegevens!$J$1) -> 0.11046 | G15: =VLOOKUP($A15,Stamgegevens!$A$8:$AE$36,Stamgegevens!$K$1) -> 10000 | H15: =VLOOKUP($A15,Stamgegevens!$A$8:$AE$36,Stamgegevens!$L$1) -> 0.08394 | I15: =VLOOKUP($A15,Stamgegevens!$A$8:$AE$36,Stamgegevens!$N$1) -> 1 | J15: =F15*I15 -> 0.11046 | L15: =VLOOKUP($A15,Stamgegevens!$A$8:$AE$36,Stamgegevens!$P$1) -> 6.18168 | M15: =VLOOKUP($A15,Stamgegevens!$A$8:$AE$36,Stamgegevens!$Q$1) -> 6.18168 | O15: =VLOOKUP($A15,Stamgegevens!$A$8:$AE$36,Stamgegevens!$S$1) -> 0.01032 | P15: =P14 -> 0.02 | Q15: =VLOOKUP($A15,Stamgegevens!$A$8:$AE$36,Stamgegevens!$U$1) -> 0 | R15: =VLOOKUP($A15,Stamgegevens!$A$8:$AE$36,Stamgegevens!$T$1) -> 0.1548 | S15: =S14 -> 0 | U15: =IF($M$3=0,$M$3,U14-365) -> 8401 | X15: =VLOOKUP($A15,Stamgegevens!$A$8:$AE$36,Stamgegevens!$W$1) -> 3.5 | Z15: =VLOOKUP($A15,Stamgegevens!$A$8:$AE$36,Stamgegevens!$Y$1) -> -0.02 | AB15: =VLOOKUP($A15,Stamgegevens!$A$8:$AE$36,Stamgegevens!$AA$1) -> 14 | AD15: =VLOOKUP($A15,Stamgegevens!$A$8:$AE$36,Stamgegevens!$AC$1) -> 0.2 | AF15: =VLOOKUP($A15,Stamgegevens!$A$8:$AE$36,Stamgegevens!$AE$1) -> 0.85
A16: =A15+1 -> 2027 | B16: 3 | D16: =VLOOKUP($A16,Stamgegevens!$A$8:$AE$36,Stamgegevens!$H$1) -> 0.025 | F16: =VLOOKUP($A16,Stamgegevens!$A$8:$AE$36,Stamgegevens!$J$1) -> 0.11046 | G16: =VLOOKUP($A16,Stamgegevens!$A$8:$AE$36,Stamgegevens!$K$1) -> 10000 | H16: =VLOOKUP($A16,Stamgegevens!$A$8:$AE$36,Stamgegevens!$L$1) -> 0.08394 | I16: =VLOOKUP($A16,Stamgegevens!$A$8:$AE$36,Stamgegevens!$N$1) -> 0 | J16: =F16*I16 -> 0 | L16: =VLOOKUP($A16,Stamgegevens!$A$8:$AE$36,Stamgegevens!$P$1) -> 6.354767 | M16: =VLOOKUP($A16,Stamgegevens!$A$8:$AE$36,Stamgegevens!$Q$1) -> 6.354767 | O16: =VLOOKUP($A16,Stamgegevens!$A$8:$AE$36,Stamgegevens!$S$1) -> 0.01060896 | P16: =P15 -> 0.02 | Q16: =VLOOKUP($A16,Stamgegevens!$A$8:$AE$36,Stamgegevens!$U$1) -> 0 | R16: =VLOOKUP($A16,Stamgegevens!$A$8:$AE$36,Stamgegevens!$T$1) -> 0.1591344 | S16: =S15 -> 0 | U16: =IF($M$3=0,$M$3,U15-365) -> 8036 | X16: =VLOOKUP($A16,Stamgegevens!$A$8:$AE$36,Stamgegevens!$W$1) -> 3.5 | Z16: =VLOOKUP($A16,Stamgegevens!$A$8:$AE$36,Stamgegevens!$Y$1) -> -0.02 | AB16: =VLOOKUP($A16,Stamgegevens!$A$8:$AE$36,Stamgegevens!$AA$1) -> 14 | AD16: =VLOOKUP($A16,Stamgegevens!$A$8:$AE$36,Stamgegevens!$AC$1) -> 0.2 | AF16: =VLOOKUP($A16,Stamgegevens!$A$8:$AE$36,Stamgegevens!$AE$1) -> 0.85
A17: =A16+1 -> 2028 | B17: 4 | D17: =VLOOKUP($A17,Stamgegevens!$A$8:$AE$36,Stamgegevens!$H$1) -> 0.025 | F17: =VLOOKUP($A17,Stamgegevens!$A$8:$AE$36,Stamgegevens!$J$1) -> 0.11046 | G17: =VLOOKUP($A17,Stamgegevens!$A$8:$AE$36,Stamgegevens!$K$1) -> 10000 | H17: =VLOOKUP($A17,Stamgegevens!$A$8:$AE$36,Stamgegevens!$L$1) -> 0.08394 | I17: =VLOOKUP($A17,Stamgegevens!$A$8:$AE$36,Stamgegevens!$N$1) -> 0 | J17: =F17*I17 -> 0 | L17: =VLOOKUP($A17,Stamgegevens!$A$8:$AE$36,Stamgegevens!$P$1) -> 6.5136362 | M17: =VLOOKUP($A17,Stamgegevens!$A$8:$AE$36,Stamgegevens!$Q$1) -> 6.5136362 | O17: =VLOOKUP($A17,Stamgegevens!$A$8:$AE$36,Stamgegevens!$S$1) -> 0.010874184 | P17: =P16 -> 0.02 | Q17: =VLOOKUP($A17,Stamgegevens!$A$8:$AE$36,Stamgegevens!$U$1) -> 0 | R17: =VLOOKUP($A17,Stamgegevens!$A$8:$AE$36,Stamgegevens!$T$1) -> 0.16311276 | S17: =S16 -> 0 | U17: =IF($M$3=0,$M$3,U16-365) -> 7671 | X17: =VLOOKUP($A17,Stamgegevens!$A$8:$AE$36,Stamgegevens!$W$1) -> 3.5 | Z17: =VLOOKUP($A17,Stamgegevens!$A$8:$AE$36,Stamgegevens!$Y$1) -> -0.02 | AB17: =VLOOKUP($A17,Stamgegevens!$A$8:$AE$36,Stamgegevens!$AA$1) -> 14 | AD17: =VLOOKUP($A17,Stamgegevens!$A$8:$AE$36,Stamgegevens!$AC$1) -> 0.2 | AF17: =VLOOKUP($A17,Stamgegevens!$A$8:$AE$36,Stamgegevens!$AE$1) -> 0.85
